Workbook

Sheet Dashboard
A1: Understanding Springfield
A3: Raw Data
A4: Descriptives
A5: Histogram
A6: Pivot tables
A7: Boxplots and T-Tests
A8: Linear Regression
A9: OR and RR
A12: Logistic Regression
A13: Survival Analysis

Sheet Raw_Data
A1: Character | B1: Job_type | C1: Sleep_hours | D1: Duff_beers | E1: Cigarettes_per_day | F1: Donuts_per_day | G1: Work_ethic | H1: Anger_level | I1: Productivity_score | J1: Fired | K1: Fired_time_days | L1: Duff_level
A2: Homer Simpson | B2: Nuclear Plant | C2: 4 | D2: 7 | E2: 11 | F2: 8 | G2: 1 | H2: 7 | I2: 30 | J2: 1 | K2: 29 | L2: =IF(SpringfieldData[[#This Row],[Duff_beers]]<=1,"Low",IF(SpringfieldData[[#This Row],[Duff_beers]]<=6,"Moderate","High")) -> High
A3: Marge Simpson | B3: Home | C3: 7 | D3: 1 | E3: 0 | F3: 0 | G3: 8 | H3: 3 | I3: 83 | J3: 0 | K3: 32 | L3: =IF(SpringfieldData[[#This Row],[Duff_beers]]<=1,"Low",IF(SpringfieldData[[#This Row],[Duff_beers]]<=6,"Moderate","High")) -> Low
A4: Bart Simpson | B4: Child | C4: 5 | D4: 0 | E4: 0 | F4: 9 | G4: 4 | H4: 6 | I4: 36 | J4: 1 | K4: 29 | L4: =IF(SpringfieldData[[#This Row],[Duff_beers]]<=1,"Low",IF(SpringfieldData[[#This Row],[Duff_beers]]<=6,"Moderate","High")) -> Low
A5: Lisa Simpson | B5: Child | C5: 8 | D5: 0 | E5: 0 | F5: 2 | G5: 9 | H5: 3 | I5: 97 | J5: 0 | K5: 44 | L5: =IF(SpringfieldData[[#This Row],[Duff_beers]]<=1,"Low",IF(SpringfieldData[[#This Row],[Duff_beers]]<=6,"Moderate","High")) -> Low
A6: Maggie Simpson | B6: Child | C6: 9 | D6: 0 | E6: 0 | F6: 0 | G6: 10 | H6: 2 | I6: 98 | J6: 0 | K6: 40 | L6: =IF(SpringfieldData[[#This Row],[Duff_beers]]<=1,"Low",IF(SpringfieldData[[#This Row],[Duff_beers]]<=6,"Moderate","High")) -> Low
A7: Abe Simpson | B7: Retirement | C7: 6 | D7: 2 | E7: 4 | F7: 3 | G7: 5 | H7: 5 | I7: 55 | J7: 1 | K7: 18 | L7: =IF(SpringfieldData[[#This Row],[Duff_beers]]<=1,"Low",IF(SpringfieldData[[#This Row],[Duff_beers]]<=6,"Moderate","High")) -> Moderate
A8: Mr Burns | B8: Nuclear Plant | C8: 6 | D8: 2 | E8: 7 | F8: 1 | G8: 8 | H8: 6 | I8: 63 | J8: 1 | K8: 15 | L8: =IF(SpringfieldData[[#This Row],[Duff_beers]]<=1,"Low",IF(SpringfieldData[[#This Row],[Duff_beers]]<=6,"Moderate","High")) -> Moderate
A9: Smithers | B9: Nuclear Plant | C9: 7 | D9: 0 | E9: 1 | F9: 1 | G9: 10 | H9: 2 | I9: 91 | J9: 0 | K9: 44 | L9: =IF(SpringfieldData[[#This Row],[Duff_beers]]<=1,"Low",IF(SpringfieldData[[#This Row],[Duff_beers]]<=6,"Moderate","High")) -> Low
A10: Ned Flanders | B10: Church | C10: 8 | D10: 0 | E10: 1 | F10: 2 | G10: 9 | H10: 2 | I10: 98 | J10: 0 | K10: 43 | L10: =IF(SpringfieldData[[#This Row],[Duff_beers]]<=1,"Low",IF(SpringfieldData[[#This Row],[Duff_beers]]<=6,"Moderate","High")) -> Low
A11: Maude Flanders | B11: Church | C11: 8 | D11: 2 | E11: 2 | F11: 1 | G11: 8 | H11: 3 | I11: 84 | J11: 0 | K11: 41 | L11: =IF(SpringfieldData[[#This Row],[Duff_beers]]<=1,"Low",IF(SpringfieldData[[#This Row],[Duff_beers]]<=6,"Moderate","High")) -> Moderate
A12: Rod Flanders | B12: Child | C12: 7 | D12: 0 | E12: 0 | F12: 2 | G12: 7 | H12: 2 | I12: 85 | J12: 0 | K12: 35 | L12: =IF(SpringfieldData[[#This Row],[Duff_beers]]<=1,"Low",IF(SpringfieldData[[#This Row],[Duff_beers]]<=6,"Moderate","High")) -> Low
A13: Todd Flanders | B13: Child | C13: 7 | D13: 0 | E13: 0 | F13: 2 | G13: 9 | H13: 4 | I13: 82 | J13: 0 | K13: 34 | L13: =IF(SpringfieldData[[#This Row],[Duff_beers]]<=1,"Low",IF(SpringfieldData[[#This Row],[Duff_beers]]<=6,"Moderate","High")) -> Low
... A51: Martin Prince | B51: Child | C51: 9 | D51: 0 | E51: 0 | F51: 1 | G51: 10 | H51: 2 | I51: 97 | J51: 0 | K51: 40 | L51: =IF(SpringfieldData[[#This Row],[Duff_beers]]<=1,"Low",IF(SpringfieldData[[#This Row],[Duff_beers]]<=6,"Moderate","High")) -> Low

Sheet Descriptives
A1: What do some of these behaviours in Springfield look like? | O1: Home
A2: Look at the formulae in the filled cells. Try to complete the rest.
A3: Some Descriptives
B4: Sleep_hours | C4: Duff_beers | D4: Cigarettes_per_day | E4: Donuts_per_day | F4: Work_ethic | G4: Anger_level
A5: Mean | B5: =AVERAGE(SpringfieldData[Sleep_hours]) -> 6.24
A6: Median | B6: =MEDIAN(SpringfieldData[Sleep_hours]) -> 6
A7: SD | B7: =STDEV(SpringfieldData[Sleep_hours]) -> 1.5059067
A8: Min | B8: =MIN(SpringfieldData[Sleep_hours]) -> 4
A9: Max | B9: =MAX(SpringfieldData[Sleep_hours]) -> 9
A13: Correlations
A14: Duff v Cigarettes | B14: =CORREL(SpringfieldData[Duff_beers],SpringfieldData[Cigarettes_per_day]) -> 0.78602126
A15: Duff v Sleep
A21: ToolPak
A22: Data → Data Analysis → Descriptive Statistics
A23: Tick Summary statistics

Sheet Histogram
A1: How are some of these behaviours distributed? | O1: Home
A4: 1. Insert > chart > histogram.
A5: 2. Select data > any column in raw_data.
A6: 3. Set the bin width.
A7: 4. Explore formatting options.
A8: 5. Describe the shape.

Sheet Pivot_Tables
A1: How to quickly compare groups? | O1: Home
A4: 1. Create a Smoker_Level column in the raw data (see how Duff_level was made).
A5: 2. Insert a pivot table (this will create a new worksheet…that is okay).
A6: 3. Set a categorical variable as a group.
A7: 4. Set a continuous variable as values = average Productivity, average Sleep, average Duff.
A8: 5. Explore.

Sheet Boxplots
A1: Do these behaviour subgroups show different levels of productivity? | O1: Home
A4: 1. Use the filter function to bring in productivity values by each category (example below).
A5: 2. Highlight > insert > charts > boxplot
A6: 3. Explore formatting options
A7: 3. Make a summary table.
B12: Duff: High | C12: Duff: Moderate | D12: Duff: Low | J12: Cat 1 | K12: Cat 2 | L12: Cat 3
B13: {=_xlfn._xlws.FILTER(SpringfieldData[Productivity_score], SpringfieldData[Duff_level]="High")} -> 30 | C13: {=_xlfn._xlws.FILTER(SpringfieldData[Productivity_score], SpringfieldData[Duff_level]="Moderate")} -> 55 | D13: {=_xlfn._xlws.FILTER(SpringfieldData[Productivity_score], SpringfieldData[Duff_level]="Low")} -> 83
B14: 34 | C14: 63 | D14: 36
B15: 27 | C15: 84 | D15: 97
B16: 30 | C16: 30 | D16: 98
B17: 54 | C17: 60 | D17: 91
B18: 30 | C18: 69 | D18: 98
B19: 80 | C19: 67 | D19: 85
B20: 35 | C20: 61 | D20: 82
B21: 31 | C21: 67 | D21: 61
B22: 30 | C22: 91 | D22: 31
B23: 45 | C23: 65 | D23: 36
B24: 29 | C24: 62 | D24: 89
C25: 55 | D25: 96
C26: 95 | D26: 97
C27: 62 | D27: 91
C28: 65 | D28: 89
D29: 59
D30: 93
D31: 62
D32: 92
D33: 66
D34: 97
A38: Summary
A39: Metric | B39: Duff: High | C39: Duff: Moderate | D39: Duff: Low
A40: Mean | B40: =AVERAGE(B13:B34) -> 37.916667 | C40: =AVERAGE(C13:C34) -> 65.6875 | D40: =AVERAGE(D13:D34) -> 78.590909
A41: Median | B41: =MEDIAN(B13:B34) -> 30.5 | C41: =MEDIAN(C13:C34) -> 64 | D41: =MEDIAN(D13:D34) -> 89
A42: SD | B42: =STDEV(B13:B34) -> 15.376832 | C42: =STDEV(C13:C34) -> 15.146919 | D42: =STDEV(D13:D34) -> 21.905988
A44: T-Test High v Mod | B44: =_xlfn.T.TEST(B13:B34,C13:C34,2,2) -> 6.1629466e-05
A45: T-Test Mod v Low | B45: =_xlfn.T.TEST(C13:C34,D13:D34,2,2) -> 0.050160778
I47: Summary
I48: Metric | J48: Cat 1 | K48: Cat 2 | L48: Cat 3
I49: Mean
I50: Median
I51: SD
...

Sheet Linear_Regression
A1: How are these behaviours associated with productivity? | O1: Home
A3: 1. Insert > chart > scatter.
A4: 2. Select data > choose variables from raw_data (hold cmd/ctrl to select non-adjacent columns).
A5: 3. Add a trendline (chart elements). Use slope, intercept and Rsq to summarise the line.
A6: 4. Explore formatting options.
A7: 5. Describe the shape.
A40: ToolPak
A41: Data → Data Analysis → Regressions
A42: Select Y, then all for X (need to be contiguous)

Sheet OR_RR
A1: What are the risks, and odds, of getting fired? | O1: Home
A2: Look at the formulae in the filled cells. Try to compile your own 2x2.
A6: Group | B6: Fired | C6: Not Fired | D6: Total | G6: Group | H6: Outcome | I6: Not | J6: Total
A7: Duff >=3 | B7: =COUNTIFS(Raw_Data!D:D, ">=3", Raw_Data!J:J, 1) -> 19 | C7: =COUNTIFS(Raw_Data!D:D, ">=3", Raw_Data!J:J, 0) -> 1 | D7: =SUM(B7:C7) -> 20 | G7: Category | J7: =SUM(H7:I7) -> 0
A8: Other | B8: =COUNTIFS(Raw_Data!D:D, "<3", Raw_Data!J:J, 1) -> 9 | C8: =COUNTIFS(Raw_Data!D:D, "<3", Raw_Data!J:J, 0) -> 21 | D8: =SUM(B8:C8) -> 30 | G8: Other | J8: =SUM(H8:I8) -> 0
A9: Total | B9: =SUM(B7:B8) -> 28 | C9: =SUM(C7:C8) -> 22 | D9: =SUM(B9:C9) -> 50 | G9: Total | H9: =SUM(H7:H8) -> 0 | I9: =SUM(I7:I8) -> 0 | J9: =SUM(H9:I9) -> 0
A12: Risks | C12: Odds | G12: Risks | I12: Odds
A13: =A7 -> Duff >=3 | B13: =B7/D7 -> 0.95 | C13: =A7 -> Duff >=3 | D13: =B7/C7 -> 19 | G13: =G7 -> Category | H13: =H7/J7 -> #DIV/0! | I13: =G7 -> Category | J13: =H7/I7 -> #DIV/0!
A14: =A8 -> Other | B14: =B8/D8 -> 0.3 | C14: =A8 -> Other | D14: =B8/C8 -> 0.42857143 | G14: =G8 -> Other | H14: =H8/J8 -> #DIV/0! | I14: =G8 -> Other | J14: =H8/I8 -> #DIV/0!
A15: RR | B15: =B13/B14 -> 3.1666667 | C15: OR | D15: =D13/D14 -> 44.333333 | G15: RR | H15: =H13/H14 -> #DIV/0! | I15: OR | J15: =J13/J14 -> #DIV/0!

Sheet Logistic_Regression
A1: When do people get fired? | O1: Home
A2: Excel lacks built-in logistic regression, so we need to go through the steps manually 😓
K4: Solver calculates regression coefficients.
C7: Sleep | D7: Duff | E7: Cigarettes | F7: Fired | G7: Logit | H7: Exp(Logit) | I7: Probability | J7: Log-Likelihood | L7: Intercept | M7: 5
B8: Homer Simpson | C8: 4 | D8: 7 | E8: 11 | F8: 1 | G8: =$M$7+$M$8*C8+$M$9*D8+$M$10*E8 -> 7.2 | H8: =EXP(G8) -> 1339.4308 | I8: =H8/(1+H8) -> 0.99925397 | J8: =IF(F8=1,LN(I8),LN(1-I8)) -> -0.00074630725 | L8: Sleep | M8: -0.7
B9: Marge Simpson | C9: 7 | D9: 1 | E9: 0 | F9: 1 | G9: =$M$7+$M$8*C9+$M$9*D9+$M$10*E9 -> 0.5 | H9: =EXP(G9) -> 1.6487213 | I9: =H9/(1+H9) -> 0.62245933 | J9: =IF(F9=1,LN(I9),LN(1-I9)) -> -0.47407698 | L9: Duff | M9: 0.4
B10: Bart Simpson | C10: 5 | D10: 0 | E10: 0 | F10: 1 | G10: =$M$7+$M$8*C10+$M$9*D10+$M$10*E10 -> 1.5 | H10: =EXP(G10) -> 4.4816891 | I10: =H10/(1+H10) -> 0.81757448 | J10: =IF(F10=1,LN(I10),LN(1-I10)) -> -0.20141328 | L10: Cigarettes | M10: 0.2
B11: Lisa Simpson | C11: 8 | D11: 0 | E11: 0 | F11: 1 | G11: =$M$7+$M$8*C11+$M$9*D11+$M$10*E11 -> -0.6 | H11: =EXP(G11) -> 0.54881164 | I11: =H11/(1+H11) -> 0.35434369 | J11: =IF(F11=1,LN(I11),LN(1-I11)) -> -1.037488
B12: Maggie Simpson | C12: 9 | D12: 0 | E12: 0 | F12: 1 | G12: =$M$7+$M$8*C12+$M$9*D12+$M$10*E12 -> -1.3 | H12: =EXP(G12) -> 0.27253179 | I12: =H12/(1+H12) -> 0.21416502 | J12: =IF(F12=1,LN(I12),LN(1-I12)) -> -1.5410085
B13: Abe Simpson | C13: 6 | D13: 2 | E13: 4 | F13: 0 | G13: =$M$7+$M$8*C13+$M$9*D13+$M$10*E13 -> 2.4 | H13: =EXP(G13) -> 11.023176 | I13: =H13/(1+H13) -> 0.9168273 | J13: =IF(F13=1,LN(I13),LN(1-I13)) -> -2.4868362 | L13: Total Log-Likelihood
B14: Mr Burns | C14: 6 | D14: 2 | E14: 7 | F14: 1 | G14: =$M$7+$M$8*C14+$M$9*D14+$M$10*E14 -> 3 | H14: =EXP(G14) -> 20.085537 | I14: =H14/(1+H14) -> 0.95257413 | J14: =IF(F14=1,LN(I14),LN(1-I14)) -> -0.048587352 | L14: =SUM(J8:J57) -> -49.48947
B15: Smithers | C15: 7 | D15: 0 | E15: 1 | F15: 0 | G15: =$M$7+$M$8*C15+$M$9*D15+$M$10*E15 -> 0.3 | H15: =EXP(G15) -> 1.3498588 | I15: =H15/(1+H15) -> 0.57444252 | J15: =IF(F15=1,LN(I15),LN(1-I15)) -> -0.85435524
B16: Ned Flanders | C16: 8 | D16: 0 | E16: 1 | F16: 1 | G16: =$M$7+$M$8*C16+$M$9*D16+$M$10*E16 -> -0.4 | H16: =EXP(G16) -> 0.67032005 | I16: =H16/(1+H16) -> 0.40131234 | J16: =IF(F16=1,LN(I16),LN(1-I16)) -> -0.91301525
B17: Maude Flanders | C17: 8 | D17: 2 | E17: 2 | F17: 1 | G17: =$M$7+$M$8*C17+$M$9*D17+$M$10*E17 -> 0.6 | H17: =EXP(G17) -> 1.8221188 | I17: =H17/(1+H17) -> 0.64565631 | J17: =IF(F17=1,LN(I17),LN(1-I17)) -> -0.43748795
B18: Rod Flanders | C18: 7 | D18: 0 | E18: 0 | F18: 0 | G18: =$M$7+$M$8*C18+$M$9*D18+$M$10*E18 -> 0.1 | H18: =EXP(G18) -> 1.1051709 | I18: =H18/(1+H18) -> 0.52497919 | J18: =IF(F18=1,LN(I18),LN(1-I18)) -> -0.74439666
B19: Todd Flanders | C19: 7 | D19: 0 | E19: 0 | F19: 1 | G19: =$M$7+$M$8*C19+$M$9*D19+$M$10*E19 -> 0.1 | H19: =EXP(G19) -> 1.1051709 | I19: =H19/(1+H19) -> 0.52497919 | J19: =IF(F19=1,LN(I19),LN(1-I19)) -> -0.64439666
B20: Milhouse Van Houten | C20: 5 | D20: 0 | E20: 0 | F20: 0 | G20: =$M$7+$M$8*C20+$M$9*D20+$M$10*E20 -> 1.5 | H20: =EXP(G20) -> 4.4816891 | I20: =H20/(1+H20) -> 0.81757448 | J20: =IF(F20=1,LN(I20),LN(1-I20)) -> -1.7014133
B21: Nelson Muntz | C21: 5 | D21: 0 | E21: 0 | F21: 0 | G21: =$M$7+$M$8*C21+$M$9*D21+$M$10*E21 -> 1.5 | H21: =EXP(G21) -> 4.4816891 | I21: =H21/(1+H21) -> 0.81757448 | J21: =IF(F21=1,LN(I21),LN(1-I21)) -> -1.7014133
B22: Ralph Wiggum | C22: 5 | D22: 0 | E22: 0 | F22: 1 | G22: =$M$7+$M$8*C22+$M$9*D22+$M$10*E22 -> 1.5 | H22: =EXP(G22) -> 4.4816891 | I22: =H22/(1+H22) -> 0.81757448 | J22: =IF(F22=1,LN(I22),LN(1-I22)) -> -0.20141328
B23: Apu Nahasapeemapetilon | C23: 8 | D23: 1 | E23: 0 | F23: 1 | G23: =$M$7+$M$8*C23+$M$9*D23+$M$10*E23 -> -0.2 | H23: =EXP(G23) -> 0.81873075 | I23: =H23/(1+H23) -> 0.450166 | J23: =IF(F23=1,LN(I23),LN(1-I23)) -> -0.79813887
B24: Moe Szyslak | C24: 4 | D24: 6 | E24: 5 | F24: 0 | G24: =$M$7+$M$8*C24+$M$9*D24+$M$10*E24 -> 5.6 | H24: =EXP(G24) -> 270.42641 | I24: =H24/(1+H24) -> 0.99631576 | J24: =IF(F24=1,LN(I24),LN(1-I24)) -> -5.603691
B25: Barney Gumble | C25: 5 | D25: 9 | E25: 8 | F25: 1 | G25: =$M$7+$M$8*C25+$M$9*D25+$M$10*E25 -> 6.7 | H25: =EXP(G25) -> 812.40583 | I25: =H25/(1+H25) -> 0.9987706 | J25: =IF(F25=1,LN(I25),LN(1-I25)) -> -0.001230155
B26: Krusty the Clown | C26: 6 | D26: 4 | E26: 1 | F26: 1 | G26: =$M$7+$M$8*C26+$M$9*D26+$M$10*E26 -> 2.6 | H26: =EXP(G26) -> 13.463738 | I26: =H26/(1+H26) -> 0.93086158 | J26: =IF(F26=1,LN(I26),LN(1-I26)) -> -0.071644692
... B57: Martin Prince | C57: 9 | D57: 0 | E57: 0 | F57: 0 | G57: =$M$7+$M$8*C57+$M$9*D57+$M$10*E57 -> -1.3 | H57: =EXP(G57) -> 0.27253179 | I57: =H57/(1+H57) -> 0.21416502 | J57: =IF(F57=1,LN(I57),LN(1-I57)) -> -0.24100845

Sheet Survival_Analysis
A1: When do people get fired? | O1: Home
A2: Excel lacks built-in survival analysis, so Kaplan-Meier needs to be manually calculated step-by-step 😭
C8: Time | D8: At risk | E8: Events | F8: Step | G8: S(t)
C9: 5 | D9: =COUNTIF(Raw_Data!K:K,">="&C9) -> 50 | E9: =COUNTIFS(Raw_Data!K:K,C9,Raw_Data!J:J,1) -> 0 | F9: =1-(E9/D9) -> 1 | G9: =F9 -> 1
C10: 10 | D10: =COUNTIF(Raw_Data!K:K,">="&C10) -> 50 | E10: =COUNTIFS(Raw_Data!K:K,C10,Raw_Data!J:J,1) -> 0 | F10: =1-(E10/D10) -> 1 | G10: =G9*F10 -> 1
C11: 15 | D11: =COUNTIF(Raw_Data!K:K,">="&C11) -> 47 | E11: =COUNTIFS(Raw_Data!K:K,C11,Raw_Data!J:J,1) -> 1 | F11: =1-(E11/D11) -> 0.9787234 | G11: =G10*F11 -> 0.9787234
C12: 20 | D12: =COUNTIF(Raw_Data!K:K,">="&C12) -> 40 | E12: =COUNTIFS(Raw_Data!K:K,C12,Raw_Data!J:J,1) -> 0 | F12: =1-(E12/D12) -> 1 | G12: =G11*F12 -> 0.9787234
C13: 25 | D13: =COUNTIF(Raw_Data!K:K,">="&C13) -> 36 | E13: =COUNTIFS(Raw_Data!K:K,C13,Raw_Data!J:J,1) -> 3 | F13: =1-(E13/D13) -> 0.91666667 | G13: =G12*F13 -> 0.89716312
C14: 30 | D14: =COUNTIF(Raw_Data!K:K,">="&C14) -> 22 | E14: =COUNTIFS(Raw_Data!K:K,C14,Raw_Data!J:J,1) -> 1 | F14: =1-(E14/D14) -> 0.95454545 | G14: =G13*F14 -> 0.85638298
C15: 35 | D15: =COUNTIF(Raw_Data!K:K,">="&C15) -> 16 | E15: =COUNTIFS(Raw_Data!K:K,C15,Raw_Data!J:J,1) -> 0 | F15: =1-(E15/D15) -> 1 | G15: =G14*F15 -> 0.85638298
C16: 40 | D16: =COUNTIF(Raw_Data!K:K,">="&C16) -> 13 | E16: =COUNTIFS(Raw_Data!K:K,C16,Raw_Data!J:J,1) -> 0 | F16: =1-(E16/D16) -> 1 | G16: =G15*F16 -> 0.85638298
C17: 45 | D17: =COUNTIF(Raw_Data!K:K,">="&C17) -> 1 | E17: =COUNTIFS(Raw_Data!K:K,C17,Raw_Data!J:J,1) -> 0 | F17: =1-(E17/D17) -> 1 | G17: =G16*F17 -> 0.85638298
F36: This is missing a step to fix the step-wise lines.
